## 2.5.1_TryCatchAndFinally.kt

```
import java.io.BufferedReader
import java.io.StringReader

fun readNumber(reader: BufferedReader): Int? {
    try {
        val line = reader.readLine()
        return Integer.parseInt(line)
    }
    catch (e: NumberFormatException) {
        return null
    }
    finally {
        reader.close()
    }
}

fun readNumber1 (reader: BufferedReader) {
    val number = try {
        Integer.parseInt(reader.readLine())
    } catch (e: NumberFormatException) {
        return
    }

    println(number)
}


fun readNumber2(reader: BufferedReader) {
    val number = try {
        Integer.parseInt(reader.readLine())
    } catch (e: NumberFormatException) {
        null
    }

    println(number)
}

fun main(args: Array<String>) {
    val reader = BufferedReader(StringReader("239"))
    println(readNumber(reader))
    
    val reader1 = BufferedReader(StringReader("240"))
    println(readNumber1(reader1))
    
    val reader2 = BufferedReader(StringReader("not a number"))
    readNumber2(reader2)
}
```

## 运行结果

```
239
240
kotlin.Unit
null
```

## 小结

整个异常处理跟Java基本类似，但是没有throw了，注意这里try catch 更加灵活，可以作为代码块，可以作为表达式一部分，
可以return返回值，也可以直接null，返回null。



